<?xml version="1.0" ?>
<!-- =================================================================================== -->
<!-- |    This document was autogenerated by xacro from stewart_platform.xacro         | -->
<!-- |    EDITING THIS FILE BY HAND IS NOT RECOMMENDED                                 | -->
<!-- =================================================================================== -->
<robot name="stewart_platform">

  <material name="silver">
  <color rgba="0.700 0.700 0.700 1.000"/>
  </material>

  <link name="world"></link>

  <joint name="base_joint" type="fixed">
    <origin rpy="0 0 0" xyz="0.0 0.0 0.0"/>
    <parent link="world"/>
    <child link="base_link"/>
  </joint>
  
  <link name="base_link">
    <inertial>
      <origin rpy="0 0 0" xyz="0.0 2.4436698758698488e-17 0.00993713642315222"/>
      <mass value="10.0"/>
      <inertia ixx="1e-3" ixy="0.0" ixz="0.0" iyy="1e-3" iyz="0.0" izz="1e-3"/>
    </inertial>
    <visual>
      <origin rpy="0 0 0" xyz="0 0 0"/>
      <geometry>
        <mesh filename="file:///home/wwd9861/stewart_platform_ws/src/stewart_platform_description/meshes/base_link.stl" scale="0.001 0.001 0.001"/>
      </geometry>
      <material name="silver"/>
    </visual>
    <collision>
      <origin rpy="0 0 0" xyz="0 0 0"/>
      <geometry>
        <mesh filename="file:///home/wwd9861/stewart_platform_ws/src/stewart_platform_description/meshes/base_link.stl" scale="0.001 0.001 0.001"/>
      </geometry>
    </collision>
  </link>
  <link name="horn_1">
    <inertial>
      <origin rpy="0 0 0" xyz="-0.012500000000000022 -0.0014999999999999528 -1.214306433183765e-17"/>
      <mass value="1.0"/>
      <inertia ixx="1e-3" ixy="0.0" ixz="0.0" iyy="1e-3" iyz="0.0" izz="1e-3"/>
    </inertial>
    <visual>
      <origin rpy="0 0 0" xyz="0.015 0.047 -0.011"/>
      <geometry>
        <mesh filename="file:///home/wwd9861/stewart_platform_ws/src/stewart_platform_description/meshes/horn_1.stl" scale="0.001 0.001 0.001"/>
      </geometry>
      <material name="silver"/>
    </visual>
  </link>
  <link name="arm_left_1">
    <inertial>
      <origin rpy="0 0 0" xyz="0.009786132198792312 0.014690642591979566 0.0351275258855272"/>
      <mass value="1.0"/>
      <inertia ixx="1e-3" ixy="0.0" ixz="0.0" iyy="1e-3" iyz="0.0" izz="1e-3"/>
    </inertial>
    <visual>
      <origin rpy="0 0 0" xyz="0.04 0.047 -0.011"/>
      <geometry>
        <mesh filename="file:///home/wwd9861/stewart_platform_ws/src/stewart_platform_description/meshes/arm_left_1.stl" scale="0.001 0.001 0.001"/>
      </geometry>
      <material name="silver"/>
    </visual>
  </link>
  <link name="horn_2">
    <inertial>
      <origin rpy="0 0 0" xyz="0.012500000000000011 -0.0014999999999999528 1.734723475976807e-18"/>
      <mass value="1.0"/>
      <inertia ixx="1e-3" ixy="0.0" ixz="0.0" iyy="1e-3" iyz="0.0" izz="1e-3"/>
    </inertial>
    <visual>
      <origin rpy="0 0 0" xyz="-0.015 0.047 -0.011"/>
      <geometry>
        <mesh filename="file:///home/wwd9861/stewart_platform_ws/src/stewart_platform_description/meshes/horn_2.stl" scale="0.001 0.001 0.001"/>
      </geometry>
      <material name="silver"/>
    </visual>
  </link>
  <link name="arm_right_1">
    <inertial>
      <origin rpy="0 0 0" xyz="-0.009815584704669575 0.014735274618961992 0.03524529255448751"/>
      <mass value="1.0"/>
      <inertia ixx="1e-3" ixy="0.0" ixz="0.0" iyy="1e-3" iyz="0.0" izz="1e-3"/>
    </inertial>
    <visual>
      <origin rpy="0 0 0" xyz="-0.04 0.047 -0.011"/>
      <geometry>
        <mesh filename="file:///home/wwd9861/stewart_platform_ws/src/stewart_platform_description/meshes/arm_right_1.stl" scale="0.001 0.001 0.001"/>
      </geometry>
      <material name="silver"/>
    </visual>
  </link>
  <link name="horn_3">
    <inertial>
      <origin rpy="0 0 0" xyz="0.007549232083545229 -0.010075698604072104 -6.938893903907228e-18"/>
      <mass value="1.0"/>
      <inertia ixx="1e-3" ixy="0.0" ixz="0.0" iyy="1e-3" iyz="0.0" izz="1e-3"/>
    </inertial>
    <visual>
      <origin rpy="0 0 0" xyz="-0.048203 -0.01051 -0.011"/>
      <geometry>
        <mesh filename="file:///home/wwd9861/stewart_platform_ws/src/stewart_platform_description/meshes/horn_3.stl" scale="0.001 0.001 0.001"/>
      </geometry>
      <material name="silver"/>
    </visual>
  </link>
  <link name="arm_left_2">
    <inertial>
      <origin rpy="0 0 0" xyz="-0.017668723102288106 0.0011328927567456504 0.03524529702948602"/>
      <mass value="1.0"/>
      <inertia ixx="1e-3" ixy="0.0" ixz="0.0" iyy="1e-3" iyz="0.0" izz="1e-3"/>
    </inertial>
    <visual>
      <origin rpy="0 0 0" xyz="-0.060703 0.011141 -0.011"/>
      <geometry>
        <mesh filename="file:///home/wwd9861/stewart_platform_ws/src/stewart_platform_description/meshes/arm_left_2.stl" scale="0.001 0.001 0.001"/>
      </geometry>
      <material name="silver"/>
    </visual>
  </link>
  <link name="horn_4">
    <inertial>
      <origin rpy="0 0 0" xyz="-0.004950767916454775 0.011575698604072017 1.0408340855860843e-17"/>
      <mass value="1.0"/>
      <inertia ixx="1e-3" ixy="0.0" ixz="0.0" iyy="1e-3" iyz="0.0" izz="1e-3"/>
    </inertial>
    <visual>
      <origin rpy="0 0 0" xyz="-0.033203 -0.03649 -0.011"/>
      <geometry>
        <mesh filename="file:///home/wwd9861/stewart_platform_ws/src/stewart_platform_description/meshes/horn_4.stl" scale="0.001 0.001 0.001"/>
      </geometry>
      <material name="silver"/>
    </visual>
  </link>
  <link name="arm_right_2">
    <inertial>
      <origin rpy="0 0 0" xyz="-0.007853135821557798 -0.015868166865345305 0.035245292554487426"/>
      <mass value="1.0"/>
      <inertia ixx="1e-3" ixy="0.0" ixz="0.0" iyy="1e-3" iyz="0.0" izz="1e-3"/>
    </inertial>
    <visual>
      <origin rpy="0 0 0" xyz="-0.020703 -0.058141 -0.011"/>
      <geometry>
        <mesh filename="file:///home/wwd9861/stewart_platform_ws/src/stewart_platform_description/meshes/arm_right_2.stl" scale="0.001 0.001 0.001"/>
      </geometry>
      <material name="silver"/>
    </visual>
  </link>
  <link name="horn_5">
    <inertial>
      <origin rpy="0 0 0" xyz="0.004950767916454778 0.01157569860407208 3.469446951953614e-18"/>
      <mass value="1.0"/>
      <inertia ixx="1e-3" ixy="0.0" ixz="0.0" iyy="1e-3" iyz="0.0" izz="1e-3"/>
    </inertial>
    <visual>
      <origin rpy="0 0 0" xyz="0.033203 -0.03649 -0.011"/>
      <geometry>
        <mesh filename="file:///home/wwd9861/stewart_platform_ws/src/stewart_platform_description/meshes/horn_5.stl" scale="0.001 0.001 0.001"/>
      </geometry>
      <material name="silver"/>
    </visual>
  </link>
  <link name="arm_left_3">
    <inertial>
      <origin rpy="0 0 0" xyz="0.007853136667601375 -0.015868169351460473 0.03524529702948592"/>
      <mass value="1.0"/>
      <inertia ixx="1e-3" ixy="0.0" ixz="0.0" iyy="1e-3" iyz="0.0" izz="1e-3"/>
    </inertial>
    <visual>
      <origin rpy="0 0 0" xyz="0.020703 -0.058141 -0.011"/>
      <geometry>
        <mesh filename="file:///home/wwd9861/stewart_platform_ws/src/stewart_platform_description/meshes/arm_left_3.stl" scale="0.001 0.001 0.001"/>
      </geometry>
      <material name="silver"/>
    </visual>
  </link>
  <link name="horn_6">
    <inertial>
      <origin rpy="0 0 0" xyz="-0.007549232083545222 -0.010075698604072043 1.734723475976807e-18"/>
      <mass value="1.0"/>
      <inertia ixx="1e-3" ixy="0.0" ixz="0.0" iyy="1e-3" iyz="0.0" izz="1e-3"/>
    </inertial>
    <visual>
      <origin rpy="0 0 0" xyz="0.048203 -0.01051 -0.011"/>
      <geometry>
        <mesh filename="file:///home/wwd9861/stewart_platform_ws/src/stewart_platform_description/meshes/horn_6.stl" scale="0.001 0.001 0.001"/>
      </geometry>
      <material name="silver"/>
    </visual>
  </link>
  <link name="arm_right_3">
    <inertial>
      <origin rpy="0 0 0" xyz="0.017668720526227373 0.001132892246383254 0.035245292554487426"/>
      <mass value="1.0"/>
      <inertia ixx="1e-3" ixy="0.0" ixz="0.0" iyy="1e-3" iyz="0.0" izz="1e-3"/>
    </inertial>
    <visual>
      <origin rpy="0 0 0" xyz="0.060703 0.011141 -0.011"/>
      <geometry>
        <mesh filename="file:///home/wwd9861/stewart_platform_ws/src/stewart_platform_description/meshes/arm_right_3.stl" scale="0.001 0.001 0.001"/>
      </geometry>
      <material name="silver"/>
    </visual>
  </link>
  <link name="platform">
    <inertial>
      <origin rpy="0 0 0" xyz="0.020098 0.01717 -0.009000225256281205"/>
      <mass value="5.0"/>
      <inertia ixx="1e-3" ixy="0.0" ixz="0.0" iyy="1e-3" iyz="0.0" izz="1e-3"/>
    </inertial>
    <visual>
      <origin rpy="0 0 0" xyz="0.0200298 0.01717 -0.082513"/>
      <geometry>
        <mesh filename="file:///home/wwd9861/stewart_platform_ws/src/stewart_platform_description/meshes/platform.stl" scale="0.001 0.001 0.001"/>
      </geometry>
      <material name="silver"/>
    </visual>
    <collision>
      <origin rpy="0 0 0" xyz="0 0 -0.082513"/>
      <geometry>
        <mesh filename="file:///home/wwd9861/stewart_platform_ws/src/stewart_platform_description/meshes/platform.stl" scale="0.001 0.001 0.001"/>
      </geometry>
    </collision>
  </link>
  <joint name="revolute1" type="revolute">
    <origin rpy="0 0 0" xyz="-0.015 -0.047 0.011"/>
    <parent link="base_link"/>
    <child link="horn_1"/>
    <axis xyz="0.0 -1.0 0.0"/>
    <limit effort="50" lower="-3.141592" upper="3.141592" velocity="20.0" />
    <dynamics damping="0.0" friction="1.0"/>
  </joint>

  <joint name="revolute2" type="revolute">
    <origin rpy="0 0 0" xyz="0.015 -0.047 0.011"/>
    <parent link="base_link"/>
    <child link="horn_2"/>
    <axis xyz="0.0 -1.0 0.0"/>
    <limit effort="50" lower="-3.141592" upper="3.141592" velocity="20.0" />
    <dynamics damping="0.0" friction="1.0"/>
  </joint>
  
  <joint name="revolute3" type="revolute">
    <origin rpy="0 0 0" xyz="0.048203 0.01051 0.011"/>
    <parent link="base_link"/>
    <child link="horn_3"/>
    <axis xyz="0.866025 0.5 0.0"/>
    <limit effort="50" lower="-3.141592" upper="3.141592" velocity="20.0" />
    <dynamics damping="0.0" friction="1.0"/>
  </joint>
  <joint name="revolute4" type="revolute">
    <origin rpy="0 0 0" xyz="0.033203 0.03649 0.011"/>
    <parent link="base_link"/>
    <child link="horn_4"/>
    <axis xyz="0.866025 0.5 0.0"/>
    <limit effort="50" lower="-3.141592" upper="3.141592" velocity="20.0" />
    <dynamics damping="0.0" friction="1.0"/>
  </joint>
  <joint name="revolute5" type="revolute">
    <origin rpy="0 0 0" xyz="-0.033203 0.03649 0.011"/>
    <parent link="base_link"/>
    <child link="horn_5"/>
    <axis xyz="-0.866025 0.5 0.0"/>
    <limit effort="50" lower="-3.141592" upper="3.141592" velocity="20.0" />
    <dynamics damping="0.0" friction="1.0"/>
  </joint>
  <joint name="revolute6" type="revolute">
    <origin rpy="0 0 0" xyz="-0.048203 0.01051 0.011"/>
    <parent link="base_link"/>
    <child link="horn_6"/>
    <axis xyz="-0.866025 0.5 0.0"/>
    <limit effort="50" lower="-3.141592" upper="3.141592" velocity="20.0" />
    <dynamics damping="0.0" friction="1.0"/>
  </joint>

  <joint name="elbow_1_1" type="continuous">
    <origin rpy="0 0 0" xyz="-0.025 0.0 0.0"/>
    <parent link="horn_1"/>
    <child link="dummy_link_1_1"/>
    <axis xyz="1.0 0.0 0.0"/>
    <dynamics damping="0.0" friction="1.0"/>
  </joint>
  <link name="dummy_link_1_1">
    <inertial>
      <origin rpy="0 0 0" xyz="0 0 0"/>
      <mass value="1.0"/>
      <inertia ixx="1e-3" ixy="0.0" ixz="0.0" iyy="1e-3" iyz="0.0" izz="1e-3"/>
    </inertial>
  </link>
  <joint name="elbow_1_2" type="continuous">
    <origin rpy="0 0 0" xyz="0 0 0"/>
    <parent link="dummy_link_1_1"/>
    <child link="dummy_link_1_2"/>
    <axis xyz="0.0 1.0 0.0"/>
    <dynamics damping="0.0" friction="1.0"/>
  </joint>
  <link name="dummy_link_1_2">
    <inertial>
      <origin rpy="0 0 0" xyz="0 0 0"/>
      <mass value="1.0"/>
      <inertia ixx="1e-3" ixy="0.0" ixz="0.0" iyy="1e-3" iyz="0.0" izz="1e-3"/>
    </inertial>
  </link>
  <joint name="elbow_1_3" type="continuous">
    <origin rpy="0 0 0" xyz="0 0 0"/>
    <parent link="dummy_link_1_2"/>
    <child link="arm_left_1"/>
    <axis xyz="0.0 0.0 1.0"/>
    <dynamics damping="0.0" friction="1.0"/>
  </joint>


  <joint name="elbow_2_1" type="continuous">
    <origin rpy="0 0 0" xyz="0.025 0.0 0.0"/>
    <parent link="horn_2"/>
    <child link="dummy_link_2_1"/>
    <axis xyz="1.0 0.0 0.0"/>
    <dynamics damping="0.0" friction="1.0"/>
  </joint>
  <link name="dummy_link_2_1">
    <inertial>
      <origin rpy="0 0 0" xyz="0 0 0"/>
      <mass value="1.0"/>
      <inertia ixx="1e-3" ixy="0.0" ixz="0.0" iyy="1e-3" iyz="0.0" izz="1e-3"/>
    </inertial>
  </link>
  <joint name="elbow_2_2" type="continuous">
    <origin rpy="0 0 0" xyz="0 0 0"/>
    <parent link="dummy_link_2_1"/>
    <child link="dummy_link_2_2"/>
    <axis xyz="0.0 1.0 0.0"/>
    <dynamics damping="0.0" friction="1.0"/>
  </joint>
  <link name="dummy_link_2_2">
    <inertial>
      <origin rpy="0 0 0" xyz="0 0 0"/>
      <mass value="1.0"/>
      <inertia ixx="1e-3" ixy="0.0" ixz="0.0" iyy="1e-3" iyz="0.0" izz="1e-3"/>
    </inertial>
  </link>
  <joint name="elbow_2_3" type="continuous">
    <origin rpy="0 0 0" xyz="0 0 0"/>
    <parent link="dummy_link_2_2"/>
    <child link="arm_right_1"/>
    <axis xyz="0.0 0.0 1.0"/>
    <dynamics damping="0.0" friction="1.0"/>
  </joint>

  <joint name="elbow_3_1" type="continuous">
    <origin rpy="0 0 0" xyz="0.0125 -0.021651 0.0"/>
    <parent link="horn_3"/>
    <child link="dummy_link_3_1"/>
    <axis xyz="1.0 0.0 0.0"/>
    <dynamics damping="0.0" friction="1.0"/>
  </joint>
  <link name="dummy_link_3_1">
    <inertial>
      <origin rpy="0 0 0" xyz="0 0 0"/>
      <mass value="1.0"/>
      <inertia ixx="1e-3" ixy="0.0" ixz="0.0" iyy="1e-3" iyz="0.0" izz="1e-3"/>
    </inertial>
  </link>
  <joint name="elbow_3_2" type="continuous">
    <origin rpy="0 0 0" xyz="0 0 0"/>
    <parent link="dummy_link_3_1"/>
    <child link="dummy_link_3_2"/>
    <axis xyz="0.0 1.0 0.0"/>
    <dynamics damping="0.0" friction="1.0"/>
  </joint>
  <link name="dummy_link_3_2">
    <inertial>
      <origin rpy="0 0 0" xyz="0 0 0"/>
      <mass value="1.0"/>
      <inertia ixx="1e-3" ixy="0.0" ixz="0.0" iyy="1e-3" iyz="0.0" izz="1e-3"/>
    </inertial>
  </link>
  <joint name="elbow_3_3" type="continuous">
    <origin rpy="0 0 0" xyz="0 0 0"/>
    <parent link="dummy_link_3_2"/>
    <child link="arm_left_2"/>
    <axis xyz="0.0 0.0 1.0"/>
    <dynamics damping="0.0" friction="1.0"/>
  </joint>

  <joint name="elbow_4_1" type="continuous">
    <origin rpy="0 0 0" xyz="-0.0125 0.021651 0.0"/>
    <parent link="horn_4"/>
    <child link="dummy_link_4_1"/>
    <axis xyz="1.0 0.0 0.0"/>
    <dynamics damping="0.0" friction="1.0"/>
  </joint>
  <link name="dummy_link_4_1">
    <inertial>
      <origin rpy="0 0 0" xyz="0 0 0"/>
      <mass value="1.0"/>
      <inertia ixx="1e-3" ixy="0.0" ixz="0.0" iyy="1e-3" iyz="0.0" izz="1e-3"/>
    </inertial>
  </link>
  <joint name="elbow_4_2" type="continuous">
    <origin rpy="0 0 0" xyz="0 0 0"/>
    <parent link="dummy_link_4_1"/>
    <child link="dummy_link_4_2"/>
    <axis xyz="0.0 1.0 0.0"/>
    <dynamics damping="0.0" friction="1.0"/>
  </joint>
  <link name="dummy_link_4_2">
    <inertial>
      <origin rpy="0 0 0" xyz="0 0 0"/>
      <mass value="1.0"/>
      <inertia ixx="1e-3" ixy="0.0" ixz="0.0" iyy="1e-3" iyz="0.0" izz="1e-3"/>
    </inertial>
  </link>
  <joint name="elbow_4_3" type="continuous">
    <origin rpy="0 0 0" xyz="0 0 0"/>
    <parent link="dummy_link_4_2"/>
    <child link="arm_right_2"/>
    <axis xyz="0.0 0.0 1.0"/>
    <dynamics damping="0.0" friction="1.0"/>
  </joint>

  <joint name="elbow_5_1" type="continuous">
    <origin rpy="0 0 0" xyz="0.0125 0.021651 0.0"/>
    <parent link="horn_5"/>
    <child link="dummy_link_5_1"/>
    <axis xyz="1.0 0.0 0.0"/>
    <dynamics damping="0.0" friction="1.0"/>
  </joint>
  <link name="dummy_link_5_1">
    <inertial>
      <origin rpy="0 0 0" xyz="0 0 0"/>
      <mass value="1.0"/>
      <inertia ixx="1e-3" ixy="0.0" ixz="0.0" iyy="1e-3" iyz="0.0" izz="1e-3"/>
    </inertial>
  </link>
  <joint name="elbow_5_2" type="continuous">
    <origin rpy="0 0 0" xyz="0 0 0"/>
    <parent link="dummy_link_5_1"/>
    <child link="dummy_link_5_2"/>
    <axis xyz="0.0 1.0 0.0"/>
    <dynamics damping="0.0" friction="1.0"/>
  </joint>
  <link name="dummy_link_5_2">
    <inertial>
      <origin rpy="0 0 0" xyz="0 0 0"/>
      <mass value="1.0"/>
      <inertia ixx="1e-3" ixy="0.0" ixz="0.0" iyy="1e-3" iyz="0.0" izz="1e-3"/>
    </inertial>
  </link>
  <joint name="elbow_5_3" type="continuous">
    <origin rpy="0 0 0" xyz="0 0 0"/>
    <parent link="dummy_link_5_2"/>
    <child link="arm_left_3"/>
    <axis xyz="0.0 0.0 1.0"/>
    <dynamics damping="0.0" friction="1.0"/>
  </joint>


  <joint name="elbow_6_1" type="continuous">
    <origin rpy="0 0 0" xyz="-0.0125 -0.021651 0.0"/>
    <parent link="horn_6"/>
    <child link="dummy_link_6_1"/>
    <axis xyz="1.0 0.0 0.0"/>
    <dynamics damping="0.0" friction="1.0"/>
  </joint>
  <link name="dummy_link_6_1">
    <inertial>
      <origin rpy="0 0 0" xyz="0 0 0"/>
      <mass value="1.0"/>
      <inertia ixx="1e-3" ixy="0.0" ixz="0.0" iyy="1e-3" iyz="0.0" izz="1e-3"/>
    </inertial>
  </link>
  <joint name="elbow_6_2" type="continuous">
    <origin rpy="0 0 0" xyz="0 0 0"/>
    <parent link="dummy_link_6_1"/>
    <child link="dummy_link_6_2"/>
    <axis xyz="0.0 1.0 0.0"/>
    <dynamics damping="0.0" friction="1.0"/>
  </joint>
  <link name="dummy_link_6_2">
    <inertial>
      <origin rpy="0 0 0" xyz="0 0 0"/>
      <mass value="1.0"/>
      <inertia ixx="1e-3" ixy="0.0" ixz="0.0" iyy="1e-3" iyz="0.0" izz="1e-3"/>
    </inertial>
  </link>
  <joint name="elbow_6_3" type="continuous">
    <origin rpy="0 0 0" xyz="0 0 0"/>
    <parent link="dummy_link_6_2"/>
    <child link="arm_right_3"/>
    <axis xyz="0.0 0.0 1.0"/>
    <dynamics damping="0.0" friction="1.0"/>
  </joint>

  <joint name="j_1_1" type="continuous">
    <origin rpy="0 0 0" xyz="0.019902 0.02983 0.071513"/>
    <parent link="arm_left_1"/>
    <child link="dummy_1_1"/>
    <axis xyz="1.0 0.0 0.0"/>
    <dynamics damping="0.0" friction="1.0"/>
  </joint>
  <link name="dummy_1_1">
    <inertial>
      <origin rpy="0 0 0" xyz="0 0 0"/>
      <mass value="1.0"/>
      <inertia ixx="1e-3" ixy="0.0" ixz="0.0" iyy="1e-3" iyz="0.0" izz="1e-3"/>
    </inertial>
  </link>
  <joint name="j_1_2" type="continuous">
    <origin rpy="0 0 0" xyz="0 0 0"/>
    <parent link="dummy_1_1"/>
    <child link="dummy_1_2"/>
    <axis xyz="0.0 1.0 0.0"/>
    <dynamics damping="0.0" friction="1.0"/>
  </joint>
  <link name="dummy_1_2">
    <inertial>
      <origin rpy="0 0 0" xyz="0 0 0"/>
      <mass value="1.0"/>
      <inertia ixx="1e-3" ixy="0.0" ixz="0.0" iyy="1e-3" iyz="0.0" izz="1e-3"/>
    </inertial>
  </link>
  <joint name="j_1_3" type="continuous">
    <origin rpy="0 0 0" xyz="0 0 0"/>
    <parent link="dummy_1_2"/>
    <child link="dummy_1_3"/>
    <axis xyz="0.0 0.0 1.0"/>
    <dynamics damping="0.0" friction="1.0"/>
  </joint>
  <link name="dummy_1_3">
    <inertial>
      <origin rpy="0 0 0" xyz="0 0 0"/>
      <mass value="1.0"/>
      <inertia ixx="1e-3" ixy="0.0" ixz="0.0" iyy="1e-3" iyz="0.0" izz="1e-3"/>
    </inertial>
  </link>
  <joint name="platform_joint_1" type="fixed">
    <origin rpy="0 0 0" xyz="0 0 0"/>
    <parent link="dummy_1_3"/>
    <child link="platform"/>
  </joint>

<joint name="j_2_1" type="continuous">
    <origin rpy="0 0 0" xyz="-0.019902 0.02983 0.071513"/>
    <parent link="arm_right_1"/>
    <child link="dummy_2_1"/>
    <axis xyz="1.0 0.0 0.0"/>
    <dynamics damping="0.0" friction="1.0"/>
  </joint>
  <link name="dummy_2_1">
    <inertial>
      <origin rpy="0 0 0" xyz="0 0 0"/>
      <mass value="1.0"/>
      <inertia ixx="1e-3" ixy="0.0" ixz="0.0" iyy="1e-3" iyz="0.0" izz="1e-3"/>
    </inertial>
  </link>
  <joint name="j_2_2" type="continuous">
    <origin rpy="0 0 0" xyz="0 0 0"/>
    <parent link="dummy_2_1"/>
    <child link="dummy_2_2"/>
    <axis xyz="0.0 1.0 0.0"/>
    <dynamics damping="0.0" friction="1.0"/>
  </joint>
  <link name="dummy_2_2">
    <inertial>
      <origin rpy="0 0 0" xyz="0 0 0"/>
      <mass value="1.0"/>
      <inertia ixx="1e-3" ixy="0.0" ixz="0.0" iyy="1e-3" iyz="0.0" izz="1e-3"/>
    </inertial>
  </link>
  <joint name="j_2_3" type="continuous">
    <origin rpy="0 0 0" xyz="0 0 0"/>
    <parent link="dummy_2_2"/>
    <child link="dummy_2_3"/>
    <axis xyz="0.0 0.0 1.0"/>
    <dynamics damping="0.0" friction="1.0"/>
  </joint>
  <link name="dummy_2_3">
    <inertial>  
      <origin rpy="0 0 0" xyz="0 0 0"/>
      <mass value="1.0"/>
      <inertia ixx="1e-3" ixy="0.0" ixz="0.0" iyy="1e-3" iyz="0.0" izz="1e-3"/>
    </inertial>
  </link>

  <joint name="j_3_1" type="continuous">
    <origin rpy="0 0 0" xyz="-0.035785 0.002321 0.071513"/>
    <parent link="arm_left_2"/>
    <child link="dummy_3_1"/>
    <axis xyz="1.0 0.0 0.0"/>
    <dynamics damping="0.0" friction="1.0"/>
  </joint>
  <link name="dummy_3_1">
    <inertial>
      <origin rpy="0 0 0" xyz="0 0 0"/>
      <mass value="1.0"/>
      <inertia ixx="1e-3" ixy="0.0" ixz="0.0" iyy="1e-3" iyz="0.0" izz="1e-3"/>
    </inertial>
  </link>
  <joint name="j_3_2" type="continuous">
    <origin rpy="0 0 0" xyz="0 0 0"/>
    <parent link="dummy_3_1"/>
    <child link="dummy_3_2"/>
    <axis xyz="0.0 1.0 0.0"/>
    <dynamics damping="0.0" friction="1.0"/>
  </joint>
  <link name="dummy_3_2">
    <inertial>
      <origin rpy="0 0 0" xyz="0 0 0"/>
      <mass value="1.0"/>
      <inertia ixx="1e-3" ixy="0.0" ixz="0.0" iyy="1e-3" iyz="0.0" izz="1e-3"/>
    </inertial>
  </link>
  <joint name="j_3_3" type="continuous">
    <origin rpy="0 0 0" xyz="0 0 0"/>
    <parent link="dummy_3_2"/>
    <child link="dummy_3_3"/>
    <axis xyz="0.0 0.0 1.0"/>
    <dynamics damping="0.0" friction="1.0"/>
  </joint>
  <link name="dummy_3_3">
    <inertial>
      <origin rpy="0 0 0" xyz="0 0 0"/>
      <mass value="1.0"/>
      <inertia ixx="1e-3" ixy="0.0" ixz="0.0" iyy="1e-3" iyz="0.0" izz="1e-3"/>
    </inertial>
  </link>

  <joint name="j_4_1" type="continuous">
    <origin rpy="0 0 0" xyz="-0.015883 -0.032151 0.071513"/>
    <parent link="arm_right_2"/>
    <child link="dummy_4_1"/>
    <axis xyz="1.0 0.0 0.0"/>
    <dynamics damping="0.0" friction="1.0"/>
  </joint>
  <link name="dummy_4_1">
    <inertial>
      <origin rpy="0 0 0" xyz="0 0 0"/>
      <mass value="1.0"/>
      <inertia ixx="1e-3" ixy="0.0" ixz="0.0" iyy="1e-3" iyz="0.0" izz="1e-3"/>
    </inertial>
  </link>
  <joint name="j_4_2" type="continuous">
    <origin rpy="0 0 0" xyz="0 0 0"/>
    <parent link="dummy_4_1"/>
    <child link="dummy_4_2"/>
    <axis xyz="0.0 1.0 0.0"/>
    <dynamics damping="0.0" friction="1.0"/>
  </joint>
  <link name="dummy_4_2">
    <inertial>
      <origin rpy="0 0 0" xyz="0 0 0"/>
      <mass value="1.0"/>
      <inertia ixx="1e-3" ixy="0.0" ixz="0.0" iyy="1e-3" iyz="0.0" izz="1e-3"/>
    </inertial>
  </link>
  <joint name="j_4_3" type="continuous">
    <origin rpy="0 0 0" xyz="0 0 0"/>
    <parent link="dummy_4_2"/>
    <child link="dummy_4_3"/>
    <axis xyz="0.0 0.0 1.0"/>
    <dynamics damping="0.0" friction="1.0"/>
  </joint>
  <link name="dummy_4_3">
    <inertial>
      <origin rpy="0 0 0" xyz="0 0 0"/>
      <mass value="1.0"/>
      <inertia ixx="1e-3" ixy="0.0" ixz="0.0" iyy="1e-3" iyz="0.0" izz="1e-3"/>
    </inertial>
  </link>

  <joint name="j_5_1" type="continuous">
    <origin rpy="0 0 0" xyz="0.015883 -0.032151 0.071513"/>
    <parent link="arm_left_3"/>
    <child link="dummy_5_1"/>
    <axis xyz="1.0 0.0 0.0"/>
    <dynamics damping="0.0" friction="1.0"/>
  </joint>
  <link name="dummy_5_1">
    <inertial>
      <origin rpy="0 0 0" xyz="0 0 0"/>
      <mass value="1.0"/>
      <inertia ixx="1e-3" ixy="0.0" ixz="0.0" iyy="1e-3" iyz="0.0" izz="1e-3"/>
    </inertial>
  </link>
  <joint name="j_5_2" type="continuous">
    <origin rpy="0 0 0" xyz="0 0 0"/>
    <parent link="dummy_5_1"/>
    <child link="dummy_5_2"/>
    <axis xyz="0.0 1.0 0.0"/>
    <dynamics damping="0.0" friction="1.0"/>
  </joint>
  <link name="dummy_5_2">
    <inertial>
      <origin rpy="0 0 0" xyz="0 0 0"/>
      <mass value="1.0"/>
      <inertia ixx="1e-3" ixy="0.0" ixz="0.0" iyy="1e-3" iyz="0.0" izz="1e-3"/>
    </inertial>
  </link>
  <joint name="j_5_3" type="continuous">
    <origin rpy="0 0 0" xyz="0 0 0"/>
    <parent link="dummy_5_2"/>
    <child link="dummy_5_3"/>
    <axis xyz="0.0 0.0 1.0"/>
    <dynamics damping="0.0" friction="1.0"/>
  </joint>
  <link name="dummy_5_3">
    <inertial>
      <origin rpy="0 0 0" xyz="0 0 0"/>
      <mass value="1.0"/>
      <inertia ixx="1e-3" ixy="0.0" ixz="0.0" iyy="1e-3" iyz="0.0" izz="1e-3"/>
    </inertial>
  </link>

  <joint name="j_6_1" type="continuous">
    <origin rpy="0 0 0" xyz="0.035785 0.002321 0.071513"/>
    <parent link="arm_right_3"/>
    <child link="dummy_6_1"/>
    <axis xyz="1.0 0.0 0.0"/>
    <dynamics damping="0.0" friction="1.0"/>
  </joint>
  <link name="dummy_6_1">
    <inertial>
      <origin rpy="0 0 0" xyz="0 0 0"/>
      <mass value="1.0"/>
      <inertia ixx="1e-3" ixy="0.0" ixz="0.0" iyy="1e-3" iyz="0.0" izz="1e-3"/>
    </inertial>
  </link>
  <joint name="j_6_2" type="continuous">
    <origin rpy="0 0 0" xyz="0 0 0"/>
    <parent link="dummy_6_1"/>
    <child link="dummy_6_2"/>
    <axis xyz="0.0 1.0 0.0"/>
    <dynamics damping="0.0" friction="1.0"/>
  </joint>
  <link name="dummy_6_2">
    <inertial>
      <origin rpy="0 0 0" xyz="0 0 0"/>
      <mass value="1.0"/>
      <inertia ixx="1e-3" ixy="0.0" ixz="0.0" iyy="1e-3" iyz="0.0" izz="1e-3"/>
    </inertial>
  </link>
  <joint name="j_6_3" type="continuous">
    <origin rpy="0 0 0" xyz="0 0 0"/>
    <parent link="dummy_6_2"/>
    <child link="dummy_6_3"/>
    <axis xyz="0.0 0.0 1.0"/>
    <dynamics damping="0.0" friction="1.0"/>
  </joint>
  <link name="dummy_6_3">
    <inertial>
      <origin rpy="0 0 0" xyz="0 0 0"/>
      <mass value="1.0"/>
      <inertia ixx="1e-3" ixy="0.0" ixz="0.0" iyy="1e-3" iyz="0.0" izz="1e-3"/>
    </inertial>
  </link> 

  <gazebo>
    <joint name="platform_joint_2" type="fixed">
      <parent>dummy_2_3</parent>
      <child>platform</child>
      <pose>0 0 0 0 0 0 </pose>
    </joint>
    <joint name="platform_joint_3" type="fixed">
      <parent>dummy_3_3</parent>
      <child>platform</child>
      <pose>0 0 0 0 0 0 </pose>
    </joint>
    <joint name="platform_joint_4" type="fixed">
      <parent>dummy_4_3</parent>
      <child>platform</child>
      <pose>0 0 0 0 0 0 </pose>
    </joint>
    <joint name="platform_joint_5" type="fixed">
      <parent>dummy_5_3</parent>
      <child>platform</child>
      <pose>0 0 0 0 0 0 </pose>
    </joint>
    <joint name="platform_joint_6" type="fixed">
      <parent>dummy_6_3</parent>
      <child>platform</child>
      <pose>0 0 0 0 0 0 </pose>
    </joint>
  </gazebo>

  <gazebo reference="base_link">
    <material>Gazebo/Gray</material>
  </gazebo>
  <gazebo reference="platform">
    <material>Gazebo/Gray</material>
  </gazebo>
  <gazebo reference="arm_left_1">
    <material>Gazebo/Black</material>
  </gazebo>
  <gazebo reference="arm_right_1">
    <material>Gazebo/Black</material>
  </gazebo>
  <gazebo reference="arm_left_2">
    <material>Gazebo/Black</material>
  </gazebo>
  <gazebo reference="arm_right_2">
    <material>Gazebo/Black</material>
  </gazebo>
  <gazebo reference="arm_left_3">
    <material>Gazebo/Black</material>
  </gazebo>
  <gazebo reference="arm_right_3">
    <material>Gazebo/Black</material>
  </gazebo>

    <ros2_control name="GazeboSystem" type="system">
    <hardware>
      <plugin>gazebo_ros2_control/GazeboSystem</plugin>
    </hardware>
    <joint name="revolute1">
      <command_interface name="effort">
      </command_interface>
      <state_interface name="position">
        <param name="initial_value">0</param>
      </state_interface>
      <state_interface name="velocity"/>
      <state_interface name="effort"/>
    </joint>
    
    <joint name="revolute2">
      <command_interface name="effort">
      </command_interface>
      <state_interface name="position">
        <param name="initial_value">0</param>
      </state_interface>
      <state_interface name="velocity"/>
      <state_interface name="effort"/>
    </joint>

    <joint name="revolute3">
      <command_interface name="effort">
      </command_interface>
      <state_interface name="position">
        <param name="initial_value">0</param>
      </state_interface>
      <state_interface name="velocity"/>
      <state_interface name="effort"/>
    </joint>

    <joint name="revolute4">
      <command_interface name="effort">
      </command_interface>
      <state_interface name="position">
        <param name="initial_value">0</param>
      </state_interface>
      <state_interface name="velocity"/>
      <state_interface name="effort"/>
    </joint>

    <joint name="revolute5">
      <command_interface name="effort">
      </command_interface>
      <state_interface name="position">
        <param name="initial_value">0</param>
      </state_interface>
      <state_interface name="velocity"/>
      <state_interface name="effort"/>
    </joint>

    <joint name="revolute6">
      <command_interface name="effort">
      </command_interface>
      <state_interface name="position">
        <param name="initial_value">0</param>
      </state_interface>
      <state_interface name="velocity"/>
      <state_interface name="effort"/>
    </joint>
  </ros2_control>

  <gazebo>
    <plugin filename="libgazebo_ros2_control.so" name="gazebo_ros2_control">
      <parameters>$(find stewart_platform_description)/config/joint_controller.yaml</parameters>
    </plugin>
  </gazebo>


</robot>